<?xml version="1.0"?>
<robot name="fd">

    <link name="fd_base"/>
    <link name="fd_x_link"/>
    <link name="fd_y_link"/>
    <link name="fd_z_link"/>
    <link name="fd_ee"/>


    <joint name="fd_x" type="prismatic">
        <origin rpy="0 0 0" xyz="0 0 0"/>
        <parent link="fd_base"/>
        <child link="fd_x_link"/>
        <axis xyz="1 0 0"/>
        <limit effort="12" velocity="1.0" lower="-2" upper="2" />
    </joint>
    <joint name="fd_y" type="prismatic">
        <origin rpy="0 0 0" xyz="0 0 0"/>
        <parent link="fd_x_link"/>
        <child link="fd_y_link"/>
        <axis xyz="0 1 0"/>
        <limit effort="12" velocity="1.0" lower="-2" upper="2" />
    </joint>
    <joint name="fd_z" type="prismatic">
        <origin rpy="0 0 0" xyz="0 0 0"/>
        <parent link="fd_y_link"/>
        <child link="fd_z_link"/>
        <axis xyz="0 0 1"/>
        <limit effort="12" velocity="1.0" lower="-2" upper="2" />
    </joint>
    <joint name="tool" type="fixed">
        <origin rpy="0 0 0" xyz="0 0 0"/>
        <parent link="fd_z_link"/>
        <child link="fd_ee"/>
    </joint>


</robot>