<?xml version="1.0" encoding='utf-8'?>
<robot xmlns:xacro="http://www.ros.org/wiki/xacro" name="fd">
    <xacro:macro name="haptic_interface" params="robot_id:='fd'">
        <link name="${robot_id}_base"/>
        <link name="${robot_id}_x_link"/>
        <link name="${robot_id}_y_link"/>
        <link name="${robot_id}_z_link"/>
        <link name="${robot_id}_ee"/>


        <joint name="${robot_id}_x" type="prismatic">
            <origin rpy="0 0 0" xyz="0 0 0"/>
            <parent link="${robot_id}_base"/>
            <child link="${robot_id}_x_link"/>
            <axis xyz="1 0 0"/>
            <limit effort="12" velocity="1.0" lower="-2" upper="2" />
        </joint>
        <joint name="${robot_id}_y" type="prismatic">
            <origin rpy="0 0 0" xyz="0 0 0"/>
            <parent link="${robot_id}_x_link"/>
            <child link="${robot_id}_y_link"/>
            <axis xyz="0 1 0"/>
            <limit effort="12" velocity="1.0" lower="-2" upper="2" />
        </joint>
        <joint name="${robot_id}_z" type="prismatic">
            <origin rpy="0 0 0" xyz="0 0 0"/>
            <parent link="${robot_id}_y_link"/>
            <child link="${robot_id}_z_link"/>
            <axis xyz="0 0 1"/>
            <limit effort="12" velocity="1.0" lower="-2" upper="2" />
        </joint>
        <joint name="tool" type="fixed">
            <origin rpy="0 0 0" xyz="0 0 0"/>
            <parent link="${robot_id}_z_link"/>
            <child link="${robot_id}_ee"/>
        </joint>
    </xacro:macro>
</robot>
